Workbook

Sheet Integrantes
B2: INTEGRANTES | C2: APORTE PRINCIPAL | D2: EVIDENCIA
B3: SCARLETT | C3: FUNCIONES Y CÁLCULOS | D3: COMMITS
B4: SCARLETT | C4: TABLAS Y GRÁFICOS | D4: COMMITS
B5: PAOLA | C5: POWERPOINT Y README | D5: COMMITS
B6: PAOLA | C6: FUNCIONES Y CÁLCULOS | D6: COMMITS
B7: TODOS | C7: REVISIÓN FINAL | D7: COMMIT FINAL

Sheet 1. Operaciones
B3: ID_Operación | C3: Fecha | D3: Cliente | E3: Código Producto | F3: País Destino | G3: Unidades | H3: Precio FOB | I3: Costo Unitario | J3: Estado | K3: Valor FOB (Free On Board | L3: Costo total | M3: Utilidad: | N3: Margen | O3: Clasificación | P3: Tipo de Mercado | Q3: Prioridad comercial | R3: Región
B4: EX001 | C4: 46027 | D4: Comercial Maya | E4: P003 | F4: Guatemala | G4: 850 | H4: 4.8 | I4: 3.2 | J4: Embarcado | K4: =+Tabla1[[#This Row],[Unidades]]*Tabla1[[#This Row],[Precio FOB]] -> 4080 | L4: =+Tabla1[[#This Row],[Unidades]]*Tabla1[[#This Row],[Costo Unitario]] -> 2720 | M4: =+Tabla1[[#This Row],[Valor FOB (Free On Board]]-Tabla1[[#This Row],[Costo total]] -> 1360 | N4: =+Tabla1[[#This Row],[Utilidad:]]/Tabla1[[#This Row],[Valor FOB (Free On Board]] -> 0.33333333 | O4: =+IF(Tabla1[[#This Row],[Valor FOB (Free On Board]]>=10000, "Grande", IF(Tabla1[[#This Row],[Valor FOB (Free On Board]]>=5000, "Mediano", "Pequeno")) -> Pequeno | P4: =VLOOKUP(Tabla1[[#This Row],[País Destino]], '3. Mercados'!$C$4:$F$9, 4, FALSE) -> Estratégico | Q4: =IF(AND(Tabla1[[#This Row],[Tipo de Mercado]]="Estratégico", Tabla1[[#This Row],[Margen]]>=30%), "Alta", IF(AND(Tabla1[[#This Row],[Tipo de Mercado]]="Estratégico", Tabla1[[#This Row],[Margen]]<30%), "Media", IF(AND(Tabla1[[#This Row],[Tipo de Mercado]]="Potencial", Tabla1[[#This Row],[Margen]]>=30%), "Media", "Baja"))) -> Alta
B5: EX002 | C5: 46034 | D5: Global Foods | E5: P001 | F5: EE.UU. | G5: 1200 | H5: 6.5 | I5: 4.1 | J5: Entregado | K5: =+Tabla1[[#This Row],[Unidades]]*Tabla1[[#This Row],[Precio FOB]] -> 7800 | L5: =+Tabla1[[#This Row],[Unidades]]*Tabla1[[#This Row],[Costo Unitario]] -> 4920 | M5: =+Tabla1[[#This Row],[Valor FOB (Free On Board]]-Tabla1[[#This Row],[Costo total]] -> 2880 | N5: =+Tabla1[[#This Row],[Utilidad:]]/Tabla1[[#This Row],[Valor FOB (Free On Board]] -> 0.36923077 | O5: =+IF(Tabla1[[#This Row],[Valor FOB (Free On Board]]>=10000, "Grande", IF(Tabla1[[#This Row],[Valor FOB (Free On Board]]>=5000, "Mediano", "Pequeno")) -> Mediano | P5: =VLOOKUP(Tabla1[[#This Row],[País Destino]], '3. Mercados'!$C$4:$F$9, 4, FALSE) -> Estratégico | Q5: =IF(AND(Tabla1[[#This Row],[Tipo de Mercado]]="Estratégico", Tabla1[[#This Row],[Margen]]>=30%), "Alta", IF(AND(Tabla1[[#This Row],[Tipo de Mercado]]="Estratégico", Tabla1[[#This Row],[Margen]]<30%), "Media", IF(AND(Tabla1[[#This Row],[Tipo de Mercado]]="Potencial", Tabla1[[#This Row],[Margen]]>=30%), "Media", "Baja"))) -> Alta | R5: =VLOOKUP(Tabla1[[#This Row],[País Destino]], '3. Mercados'!$C$4:$F$9, 2, FALSE) -> Norteamérica
B6: EX003 | C6: 46042 | D6: Distribuidora Tica | E6: P004 | F6: Costa Rica | G6: 650 | H6: 8.2 | I6: 5.9 | J6: Embarcado | K6: =+Tabla1[[#This Row],[Unidades]]*Tabla1[[#This Row],[Precio FOB]] -> 5330 | L6: =+Tabla1[[#This Row],[Unidades]]*Tabla1[[#This Row],[Costo Unitario]] -> 3835 | M6: =+Tabla1[[#This Row],[Valor FOB (Free On Board]]-Tabla1[[#This Row],[Costo total]] -> 1495 | N6: =+Tabla1[[#This Row],[Utilidad:]]/Tabla1[[#This Row],[Valor FOB (Free On Board]] -> 0.2804878 | O6: =+IF(Tabla1[[#This Row],[Valor FOB (Free On Board]]>=10000, "Grande", IF(Tabla1[[#This Row],[Valor FOB (Free On Board]]>=5000, "Mediano", "Pequeno")) -> Mediano | P6: =VLOOKUP(Tabla1[[#This Row],[País Destino]], '3. Mercados'!$C$4:$F$9, 4, FALSE) -> Estratégico | Q6: =IF(AND(Tabla1[[#This Row],[Tipo de Mercado]]="Estratégico", Tabla1[[#This Row],[Margen]]>=30%), "Alta", IF(AND(Tabla1[[#This Row],[Tipo de Mercado]]="Estratégico", Tabla1[[#This Row],[Margen]]<30%), "Media", IF(AND(Tabla1[[#This Row],[Tipo de Mercado]]="Potencial", Tabla1[[#This Row],[Margen]]>=30%), "Media", "Baja"))) -> Media
B7: EX004 | C7: 46056 | D7: Iberia Foods | E7: P002 | F7: España | G7: 950 | H7: 7.1 | I7: 4.8 | J7: Pendiente | K7: =+Tabla1[[#This Row],[Unidades]]*Tabla1[[#This Row],[Precio FOB]] -> 6745 | L7: =+Tabla1[[#This Row],[Unidades]]*Tabla1[[#This Row],[Costo Unitario]] -> 4560 | M7: =+Tabla1[[#This Row],[Valor FOB (Free On Board]]-Tabla1[[#This Row],[Costo total]] -> 2185 | N7: =+Tabla1[[#This Row],[Utilidad:]]/Tabla1[[#This Row],[Valor FOB (Free On Board]] -> 0.32394366 | O7: =+IF(Tabla1[[#This Row],[Valor FOB (Free On Board]]>=10000, "Grande", IF(Tabla1[[#This Row],[Valor FOB (Free On Board]]>=5000, "Mediano", "Pequeno")) -> Mediano | P7: =VLOOKUP(Tabla1[[#This Row],[País Destino]], '3. Mercados'!$C$4:$F$9, 4, FALSE) -> Potencial | Q7: =IF(AND(Tabla1[[#This Row],[Tipo de Mercado]]="Estratégico", Tabla1[[#This Row],[Margen]]>=30%), "Alta", IF(AND(Tabla1[[#This Row],[Tipo de Mercado]]="Estratégico", Tabla1[[#This Row],[Margen]]<30%), "Media", IF(AND(Tabla1[[#This Row],[Tipo de Mercado]]="Potencial", Tabla1[[#This Row],[Margen]]>=30%), "Media", "Baja"))) -> Media
B8: EX005 | C8: 46068 | D8: Comercial Azteca | E8: P005 | F8: México | G8: 500 | H8: 12.5 | I8: 8.7 | J8: Entregado | K8: =+Tabla1[[#This Row],[Unidades]]*Tabla1[[#This Row],[Precio FOB]] -> 6250 | L8: =+Tabla1[[#This Row],[Unidades]]*Tabla1[[#This Row],[Costo Unitario]] -> 4350 | M8: =+Tabla1[[#This Row],[Valor FOB (Free On Board]]-Tabla1[[#This Row],[Costo total]] -> 1900 | N8: =+Tabla1[[#This Row],[Utilidad:]]/Tabla1[[#This Row],[Valor FOB (Free On Board]] -> 0.304 | O8: =+IF(Tabla1[[#This Row],[Valor FOB (Free On Board]]>=10000, "Grande", IF(Tabla1[[#This Row],[Valor FOB (Free On Board]]>=5000, "Mediano", "Pequeno")) -> Mediano | P8: =VLOOKUP(Tabla1[[#This Row],[País Destino]], '3. Mercados'!$C$4:$F$9, 4, FALSE) -> Potencial | Q8: =IF(AND(Tabla1[[#This Row],[Tipo de Mercado]]="Estratégico", Tabla1[[#This Row],[Margen]]>=30%), "Alta", IF(AND(Tabla1[[#This Row],[Tipo de Mercado]]="Estratégico", Tabla1[[#This Row],[Margen]]<30%), "Media", IF(AND(Tabla1[[#This Row],[Tipo de Mercado]]="Potencial", Tabla1[[#This Row],[Margen]]>=30%), "Media", "Baja"))) -> Media
B9: EX006 | C9: 46081 | D9: Global Foods | E9: P003 | F9: EE.UU. | G9: 1400 | H9: 4.8 | I9: 3.2 | J9: Entregado | K9: =+Tabla1[[#This Row],[Unidades]]*Tabla1[[#This Row],[Precio FOB]] -> 6720 | L9: =+Tabla1[[#This Row],[Unidades]]*Tabla1[[#This Row],[Costo Unitario]] -> 4480 | M9: =+Tabla1[[#This Row],[Valor FOB (Free On Board]]-Tabla1[[#This Row],[Costo total]] -> 2240 | N9: =+Tabla1[[#This Row],[Utilidad:]]/Tabla1[[#This Row],[Valor FOB (Free On Board]] -> 0.33333333 | O9: =+IF(Tabla1[[#This Row],[Valor FOB (Free On Board]]>=10000, "Grande", IF(Tabla1[[#This Row],[Valor FOB (Free On Board]]>=5000, "Mediano", "Pequeno")) -> Mediano | P9: =VLOOKUP(Tabla1[[#This Row],[País Destino]], '3. Mercados'!$C$4:$F$9, 4, FALSE) -> Estratégico | Q9: =IF(AND(Tabla1[[#This Row],[Tipo de Mercado]]="Estratégico", Tabla1[[#This Row],[Margen]]>=30%), "Alta", IF(AND(Tabla1[[#This Row],[Tipo de Mercado]]="Estratégico", Tabla1[[#This Row],[Margen]]<30%), "Media", IF(AND(Tabla1[[#This Row],[Tipo de Mercado]]="Potencial", Tabla1[[#This Row],[Margen]]>=30%), "Media", "Baja"))) -> Alta
B10: EX007 | C10: 46089 | D10: Distribuidora Tica | E10: P001 | F10: Costa Rica | G10: 900 | H10: 6.5 | I10: 4.1 | J10: Embarcado | K10: =+Tabla1[[#This Row],[Unidades]]*Tabla1[[#This Row],[Precio FOB]] -> 5850 | L10: =+Tabla1[[#This Row],[Unidades]]*Tabla1[[#This Row],[Costo Unitario]] -> 3690 | M10: =+Tabla1[[#This Row],[Valor FOB (Free On Board]]-Tabla1[[#This Row],[Costo total]] -> 2160 | N10: =+Tabla1[[#This Row],[Utilidad:]]/Tabla1[[#This Row],[Valor FOB (Free On Board]] -> 0.36923077 | O10: =+IF(Tabla1[[#This Row],[Valor FOB (Free On Board]]>=10000, "Grande", IF(Tabla1[[#This Row],[Valor FOB (Free On Board]]>=5000, "Mediano", "Pequeno")) -> Mediano | P10: =VLOOKUP(Tabla1[[#This Row],[País Destino]], '3. Mercados'!$C$4:$F$9, 4, FALSE) -> Estratégico | Q10: =IF(AND(Tabla1[[#This Row],[Tipo de Mercado]]="Estratégico", Tabla1[[#This Row],[Margen]]>=30%), "Alta", IF(AND(Tabla1[[#This Row],[Tipo de Mercado]]="Estratégico", Tabla1[[#This Row],[Margen]]<30%), "Media", IF(AND(Tabla1[[#This Row],[Tipo de Mercado]]="Potencial", Tabla1[[#This Row],[Margen]]>=30%), "Media", "Baja"))) -> Alta | R10: =VLOOKUP(Tabla1[[#This Row],[País Destino]], '3. Mercados'!$C$4:$F$9, 2, FALSE) -> Centroamérica
B11: EX008 | C11: 46099 | D11: Comercial Maya | E11: P004 | F11: Guatemala | G11: 750 | H11: 8.2 | I11: 5.9 | J11: Entregado | K11: =+Tabla1[[#This Row],[Unidades]]*Tabla1[[#This Row],[Precio FOB]] -> 6150 | L11: =+Tabla1[[#This Row],[Unidades]]*Tabla1[[#This Row],[Costo Unitario]] -> 4425 | M11: =+Tabla1[[#This Row],[Valor FOB (Free On Board]]-Tabla1[[#This Row],[Costo total]] -> 1725 | N11: =+Tabla1[[#This Row],[Utilidad:]]/Tabla1[[#This Row],[Valor FOB (Free On Board]] -> 0.2804878 | O11: =+IF(Tabla1[[#This Row],[Valor FOB (Free On Board]]>=10000, "Grande", IF(Tabla1[[#This Row],[Valor FOB (Free On Board]]>=5000, "Mediano", "Pequeno")) -> Mediano | P11: =VLOOKUP(Tabla1[[#This Row],[País Destino]], '3. Mercados'!$C$4:$F$9, 4, FALSE) -> Estratégico | Q11: =IF(AND(Tabla1[[#This Row],[Tipo de Mercado]]="Estratégico", Tabla1[[#This Row],[Margen]]>=30%), "Alta", IF(AND(Tabla1[[#This Row],[Tipo de Mercado]]="Estratégico", Tabla1[[#This Row],[Margen]]<30%), "Media", IF(AND(Tabla1[[#This Row],[Tipo de Mercado]]="Potencial", Tabla1[[#This Row],[Margen]]>=30%), "Media", "Baja"))) -> Media
B12: EX009 | C12: 46106 | D12: Iberia Foods | E12: P005 | F12: España | G12: 600 | H12: 12.5 | I12: 8.7 | J12: Embarcado | K12: =+Tabla1[[#This Row],[Unidades]]*Tabla1[[#This Row],[Precio FOB]] -> 7500 | L12: =+Tabla1[[#This Row],[Unidades]]*Tabla1[[#This Row],[Costo Unitario]] -> 5220 | M12: =+Tabla1[[#This Row],[Valor FOB (Free On Board]]-Tabla1[[#This Row],[Costo total]] -> 2280 | N12: =+Tabla1[[#This Row],[Utilidad:]]/Tabla1[[#This Row],[Valor FOB (Free On Board]] -> 0.304 | O12: =+IF(Tabla1[[#This Row],[Valor FOB (Free On Board]]>=10000, "Grande", IF(Tabla1[[#This Row],[Valor FOB (Free On Board]]>=5000, "Mediano", "Pequeno")) -> Mediano | P12: =VLOOKUP(Tabla1[[#This Row],[País Destino]], '3. Mercados'!$C$4:$F$9, 4, FALSE) -> Potencial | Q12: =IF(AND(Tabla1[[#This Row],[Tipo de Mercado]]="Estratégico", Tabla1[[#This Row],[Margen]]>=30%), "Alta", IF(AND(Tabla1[[#This Row],[Tipo de Mercado]]="Estratégico", Tabla1[[#This Row],[Margen]]<30%), "Media", IF(AND(Tabla1[[#This Row],[Tipo de Mercado]]="Potencial", Tabla1[[#This Row],[Margen]]>=30%), "Media", "Baja"))) -> Media
B13: EX010 | C13: 46114 | D13: Comercial Azteca | E13: P002 | F13: México | G13: 1100 | H13: 7.1 | I13: 4.8 | J13: Entregado | K13: =+Tabla1[[#This Row],[Unidades]]*Tabla1[[#This Row],[Precio FOB]] -> 7810 | L13: =+Tabla1[[#This Row],[Unidades]]*Tabla1[[#This Row],[Costo Unitario]] -> 5280 | M13: =+Tabla1[[#This Row],[Valor FOB (Free On Board]]-Tabla1[[#This Row],[Costo total]] -> 2530 | N13: =+Tabla1[[#This Row],[Utilidad:]]/Tabla1[[#This Row],[Valor FOB (Free On Board]] -> 0.32394366 | O13: =+IF(Tabla1[[#This Row],[Valor FOB (Free On Board]]>=10000, "Grande", IF(Tabla1[[#This Row],[Valor FOB (Free On Board]]>=5000, "Mediano", "Pequeno")) -> Mediano | P13: =VLOOKUP(Tabla1[[#This Row],[País Destino]], '3. Mercados'!$C$4:$F$9, 4, FALSE) -> Potencial | Q13: =IF(AND(Tabla1[[#This Row],[Tipo de Mercado]]="Estratégico", Tabla1[[#This Row],[Margen]]>=30%), "Alta", IF(AND(Tabla1[[#This Row],[Tipo de Mercado]]="Estratégico", Tabla1[[#This Row],[Margen]]<30%), "Media", IF(AND(Tabla1[[#This Row],[Tipo de Mercado]]="Potencial", Tabla1[[#This Row],[Margen]]>=30%), "Media", "Baja"))) -> Media
B14: EX011 | C14: 46122 | D14: Global Foods | E14: P004 | F14: EE.UU. | G14: 1300 | H14: 8.2 | I14: 5.9 | J14: Entregado | K14: =+Tabla1[[#This Row],[Unidades]]*Tabla1[[#This Row],[Precio FOB]] -> 10660 | L14: =+Tabla1[[#This Row],[Unidades]]*Tabla1[[#This Row],[Costo Unitario]] -> 7670 | M14: =+Tabla1[[#This Row],[Valor FOB (Free On Board]]-Tabla1[[#This Row],[Costo total]] -> 2990 | N14: =+Tabla1[[#This Row],[Utilidad:]]/Tabla1[[#This Row],[Valor FOB (Free On Board]] -> 0.2804878 | O14: =+IF(Tabla1[[#This Row],[Valor FOB (Free On Board]]>=10000, "Grande", IF(Tabla1[[#This Row],[Valor FOB (Free On Board]]>=5000, "Mediano", "Pequeno")) -> Grande | P14: =VLOOKUP(Tabla1[[#This Row],[País Destino]], '3. Mercados'!$C$4:$F$9, 4, FALSE) -> Estratégico | Q14: =IF(AND(Tabla1[[#This Row],[Tipo de Mercado]]="Estratégico", Tabla1[[#This Row],[Margen]]>=30%), "Alta", IF(AND(Tabla1[[#This Row],[Tipo de Mercado]]="Estratégico", Tabla1[[#This Row],[Margen]]<30%), "Media", IF(AND(Tabla1[[#This Row],[Tipo de Mercado]]="Potencial", Tabla1[[#This Row],[Margen]]>=30%), "Media", "Baja"))) -> Media
B15: EX012 | C15: 46130 | D15: Comercial Maya | E15: P001 | F15: Guatemala | G15: 700 | H15: 6.5 | I15: 4.1 | J15: Pendiente | K15: =+Tabla1[[#This Row],[Unidades]]*Tabla1[[#This Row],[Precio FOB]] -> 4550 | L15: =+Tabla1[[#This Row],[Unidades]]*Tabla1[[#This Row],[Costo Unitario]] -> 2870 | M15: =+Tabla1[[#This Row],[Valor FOB (Free On Board]]-Tabla1[[#This Row],[Costo total]] -> 1680 | N15: =+Tabla1[[#This Row],[Utilidad:]]/Tabla1[[#This Row],[Valor FOB (Free On Board]] -> 0.36923077 | O15: =+IF(Tabla1[[#This Row],[Valor FOB (Free On Board]]>=10000, "Grande", IF(Tabla1[[#This Row],[Valor FOB (Free On Board]]>=5000, "Mediano", "Pequeno")) -> Pequeno | P15: =VLOOKUP(Tabla1[[#This Row],[País Destino]], '3. Mercados'!$C$4:$F$9, 4, FALSE) -> Estratégico | Q15: =IF(AND(Tabla1[[#This Row],[Tipo de Mercado]]="Estratégico", Tabla1[[#This Row],[Margen]]>=30%), "Alta", IF(AND(Tabla1[[#This Row],[Tipo de Mercado]]="Estratégico", Tabla1[[#This Row],[Margen]]<30%), "Media", IF(AND(Tabla1[[#This Row],[Tipo de Mercado]]="Potencial", Tabla1[[#This Row],[Margen]]>=30%), "Media", "Baja"))) -> Alta | R15: =VLOOKUP(Tabla1[[#This Row],[País Destino]], '3. Mercados'!$C$4:$F$9, 2, FALSE) -> Centroamérica
B16: EX013 | C16: 46139 | D16: Distribuidora Tica | E16: P005 | F16: Costa Rica | G16: 450 | H16: 12.5 | I16: 8.7 | J16: Embarcado | K16: =+Tabla1[[#This Row],[Unidades]]*Tabla1[[#This Row],[Precio FOB]] -> 5625 | L16: =+Tabla1[[#This Row],[Unidades]]*Tabla1[[#This Row],[Costo Unitario]] -> 3915 | M16: =+Tabla1[[#This Row],[Valor FOB (Free On Board]]-Tabla1[[#This Row],[Costo total]] -> 1710 | N16: =+Tabla1[[#This Row],[Utilidad:]]/Tabla1[[#This Row],[Valor FOB (Free On Board]] -> 0.304 | O16: =+IF(Tabla1[[#This Row],[Valor FOB (Free On Board]]>=10000, "Grande", IF(Tabla1[[#This Row],[Valor FOB (Free On Board]]>=5000, "Mediano", "Pequeno")) -> Mediano | P16: =VLOOKUP(Tabla1[[#This Row],[País Destino]], '3. Mercados'!$C$4:$F$9, 4, FALSE) -> Estratégico | Q16: =IF(AND(Tabla1[[#This Row],[Tipo de Mercado]]="Estratégico", Tabla1[[#This Row],[Margen]]>=30%), "Alta", IF(AND(Tabla1[[#This Row],[Tipo de Mercado]]="Estratégico", Tabla1[[#This Row],[Margen]]<30%), "Media", IF(AND(Tabla1[[#This Row],[Tipo de Mercado]]="Potencial", Tabla1[[#This Row],[Margen]]>=30%), "Media", "Baja"))) -> Alta
B17: EX014 | C17: 46147 | D17: Iberia Foods | E17: P003 | F17: España | G17: 1000 | H17: 4.8 | I17: 3.2 | J17: Entregado | K17: =+Tabla1[[#This Row],[Unidades]]*Tabla1[[#This Row],[Precio FOB]] -> 4800 | L17: =+Tabla1[[#This Row],[Unidades]]*Tabla1[[#This Row],[Costo Unitario]] -> 3200 | M17: =+Tabla1[[#This Row],[Valor FOB (Free On Board]]-Tabla1[[#This Row],[Costo total]] -> 1600 | N17: =+Tabla1[[#This Row],[Utilidad:]]/Tabla1[[#This Row],[Valor FOB (Free On Board]] -> 0.33333333 | O17: =+IF(Tabla1[[#This Row],[Valor FOB (Free On Board]]>=10000, "Grande", IF(Tabla1[[#This Row],[Valor FOB (Free On Board]]>=5000, "Mediano", "Pequeno")) -> Pequeno | P17: =VLOOKUP(Tabla1[[#This Row],[País Destino]], '3. Mercados'!$C$4:$F$9, 4, FALSE) -> Potencial | Q17: =IF(AND(Tabla1[[#This Row],[Tipo de Mercado]]="Estratégico", Tabla1[[#This Row],[Margen]]>=30%), "Alta", IF(AND(Tabla1[[#This Row],[Tipo de Mercado]]="Estratégico", Tabla1[[#This Row],[Margen]]<30%), "Media", IF(AND(Tabla1[[#This Row],[Tipo de Mercado]]="Potencial", Tabla1[[#This Row],[Margen]]>=30%), "Media", "Baja"))) -> Media
B18: EX015 | C18: 46156 | D18: Comercial Azteca | E18: P001 | F18: México | G18: 850 | H18: 6.5 | I18: 4.1 | J18: Embarcado | K18: =+Tabla1[[#This Row],[Unidades]]*Tabla1[[#This Row],[Precio FOB]] -> 5525 | L18: =+Tabla1[[#This Row],[Unidades]]*Tabla1[[#This Row],[Costo Unitario]] -> 3485 | M18: =+Tabla1[[#This Row],[Valor FOB (Free On Board]]-Tabla1[[#This Row],[Costo total]] -> 2040 | N18: =+Tabla1[[#This Row],[Utilidad:]]/Tabla1[[#This Row],[Valor FOB (Free On Board]] -> 0.36923077 | O18: =+IF(Tabla1[[#This Row],[Valor FOB (Free On Board]]>=10000, "Grande", IF(Tabla1[[#This Row],[Valor FOB (Free On Board]]>=5000, "Mediano", "Pequeno")) -> Mediano | P18: =VLOOKUP(Tabla1[[#This Row],[País Destino]], '3. Mercados'!$C$4:$F$9, 4, FALSE) -> Potencial | Q18: =IF(AND(Tabla1[[#This Row],[Tipo de Mercado]]="Estratégico", Tabla1[[#This Row],[Margen]]>=30%), "Alta", IF(AND(Tabla1[[#This Row],[Tipo de Mercado]]="Estratégico", Tabla1[[#This Row],[Margen]]<30%), "Media", IF(AND(Tabla1[[#This Row],[Tipo de Mercado]]="Potencial", Tabla1[[#This Row],[Margen]]>=30%), "Media", "Baja"))) -> Media | R18: =VLOOKUP(Tabla1[[#This Row],[País Destino]], '3. Mercados'!$C$4:$F$9, 2, FALSE) -> Norteamérica
B19: EX016 | C19: 46164 | D19: Global Foods | E19: P002 | F19: EE.UU. | G19: 1250 | H19: 7.1 | I19: 4.8 | J19: Entregado | K19: =+Tabla1[[#This Row],[Unidades]]*Tabla1[[#This Row],[Precio FOB]] -> 8875 | L19: =+Tabla1[[#This Row],[Unidades]]*Tabla1[[#This Row],[Costo Unitario]] -> 6000 | M19: =+Tabla1[[#This Row],[Valor FOB (Free On Board]]-Tabla1[[#This Row],[Costo total]] -> 2875 | N19: =+Tabla1[[#This Row],[Utilidad:]]/Tabla1[[#This Row],[Valor FOB (Free On Board]] -> 0.32394366 | O19: =+IF(Tabla1[[#This Row],[Valor FOB (Free On Board]]>=10000, "Grande", IF(Tabla1[[#This Row],[Valor FOB (Free On Board]]>=5000, "Mediano", "Pequeno")) -> Mediano | P19: =VLOOKUP(Tabla1[[#This Row],[País Destino]], '3. Mercados'!$C$4:$F$9, 4, FALSE) -> Estratégico | Q19: =IF(AND(Tabla1[[#This Row],[Tipo de Mercado]]="Estratégico", Tabla1[[#This Row],[Margen]]>=30%), "Alta", IF(AND(Tabla1[[#This Row],[Tipo de Mercado]]="Estratégico", Tabla1[[#This Row],[Margen]]<30%), "Media", IF(AND(Tabla1[[#This Row],[Tipo de Mercado]]="Potencial", Tabla1[[#This Row],[Margen]]>=30%), "Media", "Baja"))) -> Alta
B20: EX017 | C20: 46172 | D20: Comercial Maya | E20: P005 | F20: Guatemala | G20: 550 | H20: 12.5 | I20: 8.7 | J20: Embarcado | K20: =+Tabla1[[#This Row],[Unidades]]*Tabla1[[#This Row],[Precio FOB]] -> 6875 | L20: =+Tabla1[[#This Row],[Unidades]]*Tabla1[[#This Row],[Costo Unitario]] -> 4785 | M20: =+Tabla1[[#This Row],[Valor FOB (Free On Board]]-Tabla1[[#This Row],[Costo total]] -> 2090 | N20: =+Tabla1[[#This Row],[Utilidad:]]/Tabla1[[#This Row],[Valor FOB (Free On Board]] -> 0.304 | O20: =+IF(Tabla1[[#This Row],[Valor FOB (Free On Board]]>=10000, "Grande", IF(Tabla1[[#This Row],[Valor FOB (Free On Board]]>=5000, "Mediano", "Pequeno")) -> Mediano | P20: =VLOOKUP(Tabla1[[#This Row],[País Destino]], '3. Mercados'!$C$4:$F$9, 4, FALSE) -> Estratégico | Q20: =IF(AND(Tabla1[[#This Row],[Tipo de Mercado]]="Estratégico", Tabla1[[#This Row],[Margen]]>=30%), "Alta", IF(AND(Tabla1[[#This Row],[Tipo de Mercado]]="Estratégico", Tabla1[[#This Row],[Margen]]<30%), "Media", IF(AND(Tabla1[[#This Row],[Tipo de Mercado]]="Potencial", Tabla1[[#This Row],[Margen]]>=30%), "Media", "Baja"))) -> Alta
B21: EX018 | C21: 46180 | D21: Distribuidora Tica | E21: P003 | F21: Costa Rica | G21: 800 | H21: 4.8 | I21: 3.2 | J21: Entregado | K21: =+Tabla1[[#This Row],[Unidades]]*Tabla1[[#This Row],[Precio FOB]] -> 3840 | L21: =+Tabla1[[#This Row],[Unidades]]*Tabla1[[#This Row],[Costo Unitario]] -> 2560 | M21: =+Tabla1[[#This Row],[Valor FOB (Free On Board]]-Tabla1[[#This Row],[Costo total]] -> 1280 | N21: =+Tabla1[[#This Row],[Utilidad:]]/Tabla1[[#This Row],[Valor FOB (Free On Board]] -> 0.33333333 | O21: =+IF(Tabla1[[#This Row],[Valor FOB (Free On Board]]>=10000, "Grande", IF(Tabla1[[#This Row],[Valor FOB (Free On Board]]>=5000, "Mediano", "Pequeno")) -> Pequeno | P21: =VLOOKUP(Tabla1[[#This Row],[País Destino]], '3. Mercados'!$C$4:$F$9, 4, FALSE) -> Estratégico | Q21: =IF(AND(Tabla1[[#This Row],[Tipo de Mercado]]="Estratégico", Tabla1[[#This Row],[Margen]]>=30%), "Alta", IF(AND(Tabla1[[#This Row],[Tipo de Mercado]]="Estratégico", Tabla1[[#This Row],[Margen]]<30%), "Media", IF(AND(Tabla1[[#This Row],[Tipo de Mercado]]="Potencial", Tabla1[[#This Row],[Margen]]>=30%), "Media", "Baja"))) -> Alta
B22: EX019 | C22: 46189 | D22: Iberia Foods | E22: P004 | F22: España | G22: 900 | H22: 8.2 | I22: 5.9 | J22: Pendiente | K22: =+Tabla1[[#This Row],[Unidades]]*Tabla1[[#This Row],[Precio FOB]] -> 7380 | L22: =+Tabla1[[#This Row],[Unidades]]*Tabla1[[#This Row],[Costo Unitario]] -> 5310 | M22: =+Tabla1[[#This Row],[Valor FOB (Free On Board]]-Tabla1[[#This Row],[Costo total]] -> 2070 | N22: =+Tabla1[[#This Row],[Utilidad:]]/Tabla1[[#This Row],[Valor FOB (Free On Board]] -> 0.2804878 | O22: =+IF(Tabla1[[#This Row],[Valor FOB (Free On Board]]>=10000, "Grande", IF(Tabla1[[#This Row],[Valor FOB (Free On Board]]>=5000, "Mediano", "Pequeno")) -> Mediano | P22: =VLOOKUP(Tabla1[[#This Row],[País Destino]], '3. Mercados'!$C$4:$F$9, 4, FALSE) -> Potencial | Q22: =IF(AND(Tabla1[[#This Row],[Tipo de Mercado]]="Estratégico", Tabla1[[#This Row],[Margen]]>=30%), "Alta", IF(AND(Tabla1[[#This Row],[Tipo de Mercado]]="Estratégico", Tabla1[[#This Row],[Margen]]<30%), "Media", IF(AND(Tabla1[[#This Row],[Tipo de Mercado]]="Potencial", Tabla1[[#This Row],[Margen]]>=30%), "Media", "Baja"))) -> Baja
B23: EX020 | C23: 46198 | D23: Comercial Azteca | E23: P005 | F23: México | G23: 650 | H23: 12.5 | I23: 8.7 | J23: Entregado | K23: =+Tabla1[[#This Row],[Unidades]]*Tabla1[[#This Row],[Precio FOB]] -> 8125 | L23: =+Tabla1[[#This Row],[Unidades]]*Tabla1[[#This Row],[Costo Unitario]] -> 5655 | M23: =+Tabla1[[#This Row],[Valor FOB (Free On Board]]-Tabla1[[#This Row],[Costo total]] -> 2470 | N23: =+Tabla1[[#This Row],[Utilidad:]]/Tabla1[[#This Row],[Valor FOB (Free On Board]] -> 0.304 | O23: =+IF(Tabla1[[#This Row],[Valor FOB (Free On Board]]>=10000, "Grande", IF(Tabla1[[#This Row],[Valor FOB (Free On Board]]>=5000, "Mediano", "Pequeno")) -> Mediano | P23: =VLOOKUP(Tabla1[[#This Row],[País Destino]], '3. Mercados'!$C$4:$F$9, 4, FALSE) -> Potencial | Q23: =IF(AND(Tabla1[[#This Row],[Tipo de Mercado]]="Estratégico", Tabla1[[#This Row],[Margen]]>=30%), "Alta", IF(AND(Tabla1[[#This Row],[Tipo de Mercado]]="Estratégico", Tabla1[[#This Row],[Margen]]<30%), "Media", IF(AND(Tabla1[[#This Row],[Tipo de Mercado]]="Potencial", Tabla1[[#This Row],[Margen]]>=30%), "Media", "Baja"))) -> Media
B24: EX021 | C24: 46206 | D24: Global Foods | E24: P001 | F24: EE.UU. | G24: 1500 | H24: 6.5 | I24: 4.1 | J24: Embarcado | K24: =+Tabla1[[#This Row],[Unidades]]*Tabla1[[#This Row],[Precio FOB]] -> 9750 | L24: =+Tabla1[[#This Row],[Unidades]]*Tabla1[[#This Row],[Costo Unitario]] -> 6150 | M24: =+Tabla1[[#This Row],[Valor FOB (Free On Board]]-Tabla1[[#This Row],[Costo total]] -> 3600 | N24: =+Tabla1[[#This Row],[Utilidad:]]/Tabla1[[#This Row],[Valor FOB (Free On Board]] -> 0.36923077 | O24: =+IF(Tabla1[[#This Row],[Valor FOB (Free On Board]]>=10000, "Grande", IF(Tabla1[[#This Row],[Valor FOB (Free On Board]]>=5000, "Mediano", "Pequeno")) -> Mediano | P24: =VLOOKUP(Tabla1[[#This Row],[País Destino]], '3. Mercados'!$C$4:$F$9, 4, FALSE) -> Estratégico | Q24: =IF(AND(Tabla1[[#This Row],[Tipo de Mercado]]="Estratégico", Tabla1[[#This Row],[Margen]]>=30%), "Alta", IF(AND(Tabla1[[#This Row],[Tipo de Mercado]]="Estratégico", Tabla1[[#This Row],[Margen]]<30%), "Media", IF(AND(Tabla1[[#This Row],[Tipo de Mercado]]="Potencial", Tabla1[[#This Row],[Margen]]>=30%), "Media", "Baja"))) -> Alta | R24: =VLOOKUP(Tabla1[[#This Row],[País Destino]], '3. Mercados'!$C$4:$F$9, 2, FALSE) -> Norteamérica
B25: EX022 | C25: 46214 | D25: Comercial Maya | E25: P002 | F25: Guatemala | G25: 1000 | H25: 7.1 | I25: 4.8 | J25: Entregado | K25: =+Tabla1[[#This Row],[Unidades]]*Tabla1[[#This Row],[Precio FOB]] -> 7100 | L25: =+Tabla1[[#This Row],[Unidades]]*Tabla1[[#This Row],[Costo Unitario]] -> 4800 | M25: =+Tabla1[[#This Row],[Valor FOB (Free On Board]]-Tabla1[[#This Row],[Costo total]] -> 2300 | N25: =+Tabla1[[#This Row],[Utilidad:]]/Tabla1[[#This Row],[Valor FOB (Free On Board]] -> 0.32394366 | O25: =+IF(Tabla1[[#This Row],[Valor FOB (Free On Board]]>=10000, "Grande", IF(Tabla1[[#This Row],[Valor FOB (Free On Board]]>=5000, "Mediano", "Pequeno")) -> Mediano | P25: =VLOOKUP(Tabla1[[#This Row],[País Destino]], '3. Mercados'!$C$4:$F$9, 4, FALSE) -> Estratégico | Q25: =IF(AND(Tabla1[[#This Row],[Tipo de Mercado]]="Estratégico", Tabla1[[#This Row],[Margen]]>=30%), "Alta", IF(AND(Tabla1[[#This Row],[Tipo de Mercado]]="Estratégico", Tabla1[[#This Row],[Margen]]<30%), "Media", IF(AND(Tabla1[[#This Row],[Tipo de Mercado]]="Potencial", Tabla1[[#This Row],[Margen]]>=30%), "Media", "Baja"))) -> Alta
B26: EX023 | C26: 46222 | D26: Distribuidora Tica | E26: P004 | F26: Costa Rica | G26: 720 | H26: 8.2 | I26: 5.9 | J26: Embarcado | K26: =+Tabla1[[#This Row],[Unidades]]*Tabla1[[#This Row],[Precio FOB]] -> 5904 | L26: =+Tabla1[[#This Row],[Unidades]]*Tabla1[[#This Row],[Costo Unitario]] -> 4248 | M26: =+Tabla1[[#This Row],[Valor FOB (Free On Board]]-Tabla1[[#This Row],[Costo total]] -> 1656 | N26: =+Tabla1[[#This Row],[Utilidad:]]/Tabla1[[#This Row],[Valor FOB (Free On Board]] -> 0.2804878 | O26: =+IF(Tabla1[[#This Row],[Valor FOB (Free On Board]]>=10000, "Grande", IF(Tabla1[[#This Row],[Valor FOB (Free On Board]]>=5000, "Mediano", "Pequeno")) -> Mediano | P26: =VLOOKUP(Tabla1[[#This Row],[País Destino]], '3. Mercados'!$C$4:$F$9, 4, FALSE) -> Estratégico | Q26: =IF(AND(Tabla1[[#This Row],[Tipo de Mercado]]="Estratégico", Tabla1[[#This Row],[Margen]]>=30%), "Alta", IF(AND(Tabla1[[#This Row],[Tipo de Mercado]]="Estratégico", Tabla1[[#This Row],[Margen]]<30%), "Media", IF(AND(Tabla1[[#This Row],[Tipo de Mercado]]="Potencial", Tabla1[[#This Row],[Margen]]>=30%), "Media", "Baja"))) -> Media
B27: EX024 | C27: 46231 | D27: Iberia Foods | E27: P003 | F27: España | G27: 1150 | H27: 4.8 | I27: 3.2 | J27: Entregado | K27: =+Tabla1[[#This Row],[Unidades]]*Tabla1[[#This Row],[Precio FOB]] -> 5520 | L27: =+Tabla1[[#This Row],[Unidades]]*Tabla1[[#This Row],[Costo Unitario]] -> 3680 | M27: =+Tabla1[[#This Row],[Valor FOB (Free On Board]]-Tabla1[[#This Row],[Costo total]] -> 1840 | N27: =+Tabla1[[#This Row],[Utilidad:]]/Tabla1[[#This Row],[Valor FOB (Free On Board]] -> 0.33333333 | O27: =+IF(Tabla1[[#This Row],[Valor FOB (Free On Board]]>=10000, "Grande", IF(Tabla1[[#This Row],[Valor FOB (Free On Board]]>=5000, "Mediano", "Pequeno")) -> Mediano | P27: =VLOOKUP(Tabla1[[#This Row],[País Destino]], '3. Mercados'!$C$4:$F$9, 4, FALSE) -> Potencial | Q27: =IF(AND(Tabla1[[#This Row],[Tipo de Mercado]]="Estratégico", Tabla1[[#This Row],[Margen]]>=30%), "Alta", IF(AND(Tabla1[[#This Row],[Tipo de Mercado]]="Estratégico", Tabla1[[#This Row],[Margen]]<30%), "Media", IF(AND(Tabla1[[#This Row],[Tipo de Mercado]]="Potencial", Tabla1[[#This Row],[Margen]]>=30%), "Media", "Baja"))) -> Media
B28: EX025 | C28: 46239 | D28: Comercial Azteca | E28: P001 | F28: México | G28: 950 | H28: 6.5 | I28: 4.1 | J28: Pendiente | K28: =+Tabla1[[#This Row],[Unidades]]*Tabla1[[#This Row],[Precio FOB]] -> 6175 | L28: =+Tabla1[[#This Row],[Unidades]]*Tabla1[[#This Row],[Costo Unitario]] -> 3895 | M28: =+Tabla1[[#This Row],[Valor FOB (Free On Board]]-Tabla1[[#This Row],[Costo total]] -> 2280 | N28: =+Tabla1[[#This Row],[Utilidad:]]/Tabla1[[#This Row],[Valor FOB (Free On Board]] -> 0.36923077 | O28: =+IF(Tabla1[[#This Row],[Valor FOB (Free On Board]]>=10000, "Grande", IF(Tabla1[[#This Row],[Valor FOB (Free On Board]]>=5000, "Mediano", "Pequeno")) -> Mediano | P28: =VLOOKUP(Tabla1[[#This Row],[País Destino]], '3. Mercados'!$C$4:$F$9, 4, FALSE) -> Potencial | Q28: =IF(AND(Tabla1[[#This Row],[Tipo de Mercado]]="Estratégico", Tabla1[[#This Row],[Margen]]>=30%), "Alta", IF(AND(Tabla1[[#This Row],[Tipo de Mercado]]="Estratégico", Tabla1[[#This Row],[Margen]]<30%), "Media", IF(AND(Tabla1[[#This Row],[Tipo de Mercado]]="Potencial", Tabla1[[#This Row],[Margen]]>=30%), "Media", "Baja"))) -> Media | R28: =VLOOKUP(Tabla1[[#This Row],[País Destino]], '3. Mercados'!$C$4:$F$9, 2, FALSE) -> Norteamérica
B29: EX026 | C29: 46247 | D29: Global Foods | E29: P005 | F29: EE.UU. | G29: 700 | H29: 12.5 | I29: 8.7 | J29: Entregado | K29: =+Tabla1[[#This Row],[Unidades]]*Tabla1[[#This Row],[Precio FOB]] -> 8750 | L29: =+Tabla1[[#This Row],[Unidades]]*Tabla1[[#This Row],[Costo Unitario]] -> 6090 | M29: =+Tabla1[[#This Row],[Valor FOB (Free On Board]]-Tabla1[[#This Row],[Costo total]] -> 2660 | N29: =+Tabla1[[#This Row],[Utilidad:]]/Tabla1[[#This Row],[Valor FOB (Free On Board]] -> 0.304 | O29: =+IF(Tabla1[[#This Row],[Valor FOB (Free On Board]]>=10000, "Grande", IF(Tabla1[[#This Row],[Valor FOB (Free On Board]]>=5000, "Mediano", "Pequeno")) -> Mediano | P29: =VLOOKUP(Tabla1[[#This Row],[País Destino]], '3. Mercados'!$C$4:$F$9, 4, FALSE) -> Estratégico | Q29: =IF(AND(Tabla1[[#This Row],[Tipo de Mercado]]="Estratégico", Tabla1[[#This Row],[Margen]]>=30%), "Alta", IF(AND(Tabla1[[#This Row],[Tipo de Mercado]]="Estratégico", Tabla1[[#This Row],[Margen]]<30%), "Media", IF(AND(Tabla1[[#This Row],[Tipo de Mercado]]="Potencial", Tabla1[[#This Row],[Margen]]>=30%), "Media", "Baja"))) -> Alta
B30: EX027 | C30: 46255 | D30: Comercial Maya | E30: P003 | F30: Guatemala | G30: 1050 | H30: 4.8 | I30: 3.2 | J30: Embarcado | K30: =+Tabla1[[#This Row],[Unidades]]*Tabla1[[#This Row],[Precio FOB]] -> 5040 | L30: =+Tabla1[[#This Row],[Unidades]]*Tabla1[[#This Row],[Costo Unitario]] -> 3360 | M30: =+Tabla1[[#This Row],[Valor FOB (Free On Board]]-Tabla1[[#This Row],[Costo total]] -> 1680 | N30: =+Tabla1[[#This Row],[Utilidad:]]/Tabla1[[#This Row],[Valor FOB (Free On Board]] -> 0.33333333 | O30: =+IF(Tabla1[[#This Row],[Valor FOB (Free On Board]]>=10000, "Grande", IF(Tabla1[[#This Row],[Valor FOB (Free On Board]]>=5000, "Mediano", "Pequeno")) -> Mediano | P30: =VLOOKUP(Tabla1[[#This Row],[País Destino]], '3. Mercados'!$C$4:$F$9, 4, FALSE) -> Estratégico | Q30: =IF(AND(Tabla1[[#This Row],[Tipo de Mercado]]="Estratégico", Tabla1[[#This Row],[Margen]]>=30%), "Alta", IF(AND(Tabla1[[#This Row],[Tipo de Mercado]]="Estratégico", Tabla1[[#This Row],[Margen]]<30%), "Media", IF(AND(Tabla1[[#This Row],[Tipo de Mercado]]="Potencial", Tabla1[[#This Row],[Margen]]>=30%), "Media", "Baja"))) -> Alta
B31: EX028 | C31: 46263 | D31: Distribuidora Tica | E31: P002 | F31: Costa Rica | G31: 850 | H31: 7.1 | I31: 4.8 | J31: Entregado | K31: =+Tabla1[[#This Row],[Unidades]]*Tabla1[[#This Row],[Precio FOB]] -> 6035 | L31: =+Tabla1[[#This Row],[Unidades]]*Tabla1[[#This Row],[Costo Unitario]] -> 4080 | M31: =+Tabla1[[#This Row],[Valor FOB (Free On Board]]-Tabla1[[#This Row],[Costo total]] -> 1955 | N31: =+Tabla1[[#This Row],[Utilidad:]]/Tabla1[[#This Row],[Valor FOB (Free On Board]] -> 0.32394366 | O31: =+IF(Tabla1[[#This Row],[Valor FOB (Free On Board]]>=10000, "Grande", IF(Tabla1[[#This Row],[Valor FOB (Free On Board]]>=5000, "Mediano", "Pequeno")) -> Mediano | P31: =VLOOKUP(Tabla1[[#This Row],[País Destino]], '3. Mercados'!$C$4:$F$9, 4, FALSE) -> Estratégico | Q31: =IF(AND(Tabla1[[#This Row],[Tipo de Mercado]]="Estratégico", Tabla1[[#This Row],[Margen]]>=30%), "Alta", IF(AND(Tabla1[[#This Row],[Tipo de Mercado]]="Estratégico", Tabla1[[#This Row],[Margen]]<30%), "Media", IF(AND(Tabla1[[#This Row],[Tipo de Mercado]]="Potencial", Tabla1[[#This Row],[Margen]]>=30%), "Media", "Baja"))) -> Alta
B32: EX029 | C32: 46269 | D32: Iberia Foods | E32: P001 | F32: España | G32: 1200 | H32: 6.5 | I32: 4.1 | J32: Embarcado | K32: =+Tabla1[[#This Row],[Unidades]]*Tabla1[[#This Row],[Precio FOB]] -> 7800 | L32: =+Tabla1[[#This Row],[Unidades]]*Tabla1[[#This Row],[Costo Unitario]] -> 4920 | M32: =+Tabla1[[#This Row],[Valor FOB (Free On Board]]-Tabla1[[#This Row],[Costo total]] -> 2880 | N32: =+Tabla1[[#This Row],[Utilidad:]]/Tabla1[[#This Row],[Valor FOB (Free On Board]] -> 0.36923077 | O32: =+IF(Tabla1[[#This Row],[Valor FOB (Free On Board]]>=10000, "Grande", IF(Tabla1[[#This Row],[Valor FOB (Free On Board]]>=5000, "Mediano", "Pequeno")) -> Mediano | P32: =VLOOKUP(Tabla1[[#This Row],[País Destino]], '3. Mercados'!$C$4:$F$9, 4, FALSE) -> Potencial | Q32: =IF(AND(Tabla1[[#This Row],[Tipo de Mercado]]="Estratégico", Tabla1[[#This Row],[Margen]]>=30%), "Alta", IF(AND(Tabla1[[#This Row],[Tipo de Mercado]]="Estratégico", Tabla1[[#This Row],[Margen]]<30%), "Media", IF(AND(Tabla1[[#This Row],[Tipo de Mercado]]="Potencial", Tabla1[[#This Row],[Margen]]>=30%), "Media", "Baja"))) -> Media | R32: =VLOOKUP(Tabla1[[#This Row],[País Destino]], '3. Mercados'!$C$4:$F$9, 2, FALSE) -> Europa
B33: EX030 | C33: 46277 | D33: Comercial Azteca | E33: P004 | F33: México | G33: 600 | H33: 8.2 | I33: 5.9 | J33: Entregado | K33: =+Tabla1[[#This Row],[Unidades]]*Tabla1[[#This Row],[Precio FOB]] -> 4920 | L33: =+Tabla1[[#This Row],[Unidades]]*Tabla1[[#This Row],[Costo Unitario]] -> 3540 | M33: =+Tabla1[[#This Row],[Valor FOB (Free On Board]]-Tabla1[[#This Row],[Costo total]] -> 1380 | N33: =+Tabla1[[#This Row],[Utilidad:]]/Tabla1[[#This Row],[Valor FOB (Free On Board]] -> 0.2804878 | O33: =+IF(Tabla1[[#This Row],[Valor FOB (Free On Board]]>=10000, "Grande", IF(Tabla1[[#This Row],[Valor FOB (Free On Board]]>=5000, "Mediano", "Pequeno")) -> Pequeno | P33: =VLOOKUP(Tabla1[[#This Row],[País Destino]], '3. Mercados'!$C$4:$F$9, 4, FALSE) -> Potencial | Q33: =IF(AND(Tabla1[[#This Row],[Tipo de Mercado]]="Estratégico", Tabla1[[#This Row],[Margen]]>=30%), "Alta", IF(AND(Tabla1[[#This Row],[Tipo de Mercado]]="Estratégico", Tabla1[[#This Row],[Margen]]<30%), "Media", IF(AND(Tabla1[[#This Row],[Tipo de Mercado]]="Potencial", Tabla1[[#This Row],[Margen]]>=30%), "Media", "Baja"))) -> Baja
B34: EX031 | C34: 46285 | D34: Global Foods | E34: P003 | F34: EE.UU. | G34: 1350 | H34: 4.8 | I34: 3.2 | J34: Entregado | K34: =+Tabla1[[#This Row],[Unidades]]*Tabla1[[#This Row],[Precio FOB]] -> 6480 | L34: =+Tabla1[[#This Row],[Unidades]]*Tabla1[[#This Row],[Costo Unitario]] -> 4320 | M34: =+Tabla1[[#This Row],[Valor FOB (Free On Board]]-Tabla1[[#This Row],[Costo total]] -> 2160 | N34: =+Tabla1[[#This Row],[Utilidad:]]/Tabla1[[#This Row],[Valor FOB (Free On Board]] -> 0.33333333 | O34: =+IF(Tabla1[[#This Row],[Valor FOB (Free On Board]]>=10000, "Grande", IF(Tabla1[[#This Row],[Valor FOB (Free On Board]]>=5000, "Mediano", "Pequeno")) -> Mediano | P34: =VLOOKUP(Tabla1[[#This Row],[País Destino]], '3. Mercados'!$C$4:$F$9, 4, FALSE) -> Estratégico | Q34: =IF(AND(Tabla1[[#This Row],[Tipo de Mercado]]="Estratégico", Tabla1[[#This Row],[Margen]]>=30%), "Alta", IF(AND(Tabla1[[#This Row],[Tipo de Mercado]]="Estratégico", Tabla1[[#This Row],[Margen]]<30%), "Media", IF(AND(Tabla1[[#This Row],[Tipo de Mercado]]="Potencial", Tabla1[[#This Row],[Margen]]>=30%), "Media", "Baja"))) -> Alta
B35: EX032 | C35: 46293 | D35: Comercial Maya | E35: P005 | F35: Guatemala | G35: 500 | H35: 12.5 | I35: 8.7 | J35: Pendiente | K35: =+Tabla1[[#This Row],[Unidades]]*Tabla1[[#This Row],[Precio FOB]] -> 6250 | L35: =+Tabla1[[#This Row],[Unidades]]*Tabla1[[#This Row],[Costo Unitario]] -> 4350 | M35: =+Tabla1[[#This Row],[Valor FOB (Free On Board]]-Tabla1[[#This Row],[Costo total]] -> 1900 | N35: =+Tabla1[[#This Row],[Utilidad:]]/Tabla1[[#This Row],[Valor FOB (Free On Board]] -> 0.304 | O35: =+IF(Tabla1[[#This Row],[Valor FOB (Free On Board]]>=10000, "Grande", IF(Tabla1[[#This Row],[Valor FOB (Free On Board]]>=5000, "Mediano", "Pequeno")) -> Mediano | P35: =VLOOKUP(Tabla1[[#This Row],[País Destino]], '3. Mercados'!$C$4:$F$9, 4, FALSE) -> Estratégico | Q35: =IF(AND(Tabla1[[#This Row],[Tipo de Mercado]]="Estratégico", Tabla1[[#This Row],[Margen]]>=30%), "Alta", IF(AND(Tabla1[[#This Row],[Tipo de Mercado]]="Estratégico", Tabla1[[#This Row],[Margen]]<30%), "Media", IF(AND(Tabla1[[#This Row],[Tipo de Mercado]]="Potencial", Tabla1[[#This Row],[Margen]]>=30%), "Media", "Baja"))) -> Alta
B36: EX033 | C36: 46301 | D36: Distribuidora Tica | E36: P001 | F36: Costa Rica | G36: 950 | H36: 6.5 | I36: 4.1 | J36: Embarcado | K36: =+Tabla1[[#This Row],[Unidades]]*Tabla1[[#This Row],[Precio FOB]] -> 6175 | L36: =+Tabla1[[#This Row],[Unidades]]*Tabla1[[#This Row],[Costo Unitario]] -> 3895 | M36: =+Tabla1[[#This Row],[Valor FOB (Free On Board]]-Tabla1[[#This Row],[Costo total]] -> 2280 | N36: =+Tabla1[[#This Row],[Utilidad:]]/Tabla1[[#This Row],[Valor FOB (Free On Board]] -> 0.36923077 | O36: =+IF(Tabla1[[#This Row],[Valor FOB (Free On Board]]>=10000, "Grande", IF(Tabla1[[#This Row],[Valor FOB (Free On Board]]>=5000, "Mediano", "Pequeno")) -> Mediano | P36: =VLOOKUP(Tabla1[[#This Row],[País Destino]], '3. Mercados'!$C$4:$F$9, 4, FALSE) -> Estratégico | Q36: =IF(AND(Tabla1[[#This Row],[Tipo de Mercado]]="Estratégico", Tabla1[[#This Row],[Margen]]>=30%), "Alta", IF(AND(Tabla1[[#This Row],[Tipo de Mercado]]="Estratégico", Tabla1[[#This Row],[Margen]]<30%), "Media", IF(AND(Tabla1[[#This Row],[Tipo de Mercado]]="Potencial", Tabla1[[#This Row],[Margen]]>=30%), "Media", "Baja"))) -> Alta | R36: =VLOOKUP(Tabla1[[#This Row],[País Destino]], '3. Mercados'!$C$4:$F$9, 2, FALSE) -> Centroamérica
B37: EX034 | C37: 46309 | D37: Iberia Foods | E37: P002 | F37: España | G37: 1050 | H37: 7.1 | I37: 4.8 | J37: Entregado | K37: =+Tabla1[[#This Row],[Unidades]]*Tabla1[[#This Row],[Precio FOB]] -> 7455 | L37: =+Tabla1[[#This Row],[Unidades]]*Tabla1[[#This Row],[Costo Unitario]] -> 5040 | M37: =+Tabla1[[#This Row],[Valor FOB (Free On Board]]-Tabla1[[#This Row],[Costo total]] -> 2415 | N37: =+Tabla1[[#This Row],[Utilidad:]]/Tabla1[[#This Row],[Valor FOB (Free On Board]] -> 0.32394366 | O37: =+IF(Tabla1[[#This Row],[Valor FOB (Free On Board]]>=10000, "Grande", IF(Tabla1[[#This Row],[Valor FOB (Free On Board]]>=5000, "Mediano", "Pequeno")) -> Mediano | P37: =VLOOKUP(Tabla1[[#This Row],[País Destino]], '3. Mercados'!$C$4:$F$9, 4, FALSE) -> Potencial | Q37: =IF(AND(Tabla1[[#This Row],[Tipo de Mercado]]="Estratégico", Tabla1[[#This Row],[Margen]]>=30%), "Alta", IF(AND(Tabla1[[#This Row],[Tipo de Mercado]]="Estratégico", Tabla1[[#This Row],[Margen]]<30%), "Media", IF(AND(Tabla1[[#This Row],[Tipo de Mercado]]="Potencial", Tabla1[[#This Row],[Margen]]>=30%), "Media", "Baja"))) -> Media
B38: EX035 | C38: 46317 | D38: Comercial Azteca | E38: P003 | F38: México | G38: 750 | H38: 4.8 | I38: 3.2 | J38: Embarcado | K38: =+Tabla1[[#This Row],[Unidades]]*Tabla1[[#This Row],[Precio FOB]] -> 3600 | L38: =+Tabla1[[#This Row],[Unidades]]*Tabla1[[#This Row],[Costo Unitario]] -> 2400 | M38: =+Tabla1[[#This Row],[Valor FOB (Free On Board]]-Tabla1[[#This Row],[Costo total]] -> 1200 | N38: =+Tabla1[[#This Row],[Utilidad:]]/Tabla1[[#This Row],[Valor FOB (Free On Board]] -> 0.33333333 | O38: =+IF(Tabla1[[#This Row],[Valor FOB (Free On Board]]>=10000, "Grande", IF(Tabla1[[#This Row],[Valor FOB (Free On Board]]>=5000, "Mediano", "Pequeno")) -> Pequeno | P38: =VLOOKUP(Tabla1[[#This Row],[País Destino]], '3. Mercados'!$C$4:$F$9, 4, FALSE) -> Potencial | Q38: =IF(AND(Tabla1[[#This Row],[Tipo de Mercado]]="Estratégico", Tabla1[[#This Row],[Margen]]>=30%), "Alta", IF(AND(Tabla1[[#This Row],[Tipo de Mercado]]="Estratégico", Tabla1[[#This Row],[Margen]]<30%), "Media", IF(AND(Tabla1[[#This Row],[Tipo de Mercado]]="Potencial", Tabla1[[#This Row],[Margen]]>=30%), "Media", "Baja"))) -> Media
B39: EX036 | C39: 46325 | D39: Global Foods | E39: P004 | F39: EE.UU. | G39: 900 | H39: 8.2 | I39: 5.9 | J39: Entregado | K39: =+Tabla1[[#This Row],[Unidades]]*Tabla1[[#This Row],[Precio FOB]] -> 7380 | L39: =+Tabla1[[#This Row],[Unidades]]*Tabla1[[#This Row],[Costo Unitario]] -> 5310 | M39: =+Tabla1[[#This Row],[Valor FOB (Free On Board]]-Tabla1[[#This Row],[Costo total]] -> 2070 | N39: =+Tabla1[[#This Row],[Utilidad:]]/Tabla1[[#This Row],[Valor FOB (Free On Board]] -> 0.2804878 | O39: =+IF(Tabla1[[#This Row],[Valor FOB (Free On Board]]>=10000, "Grande", IF(Tabla1[[#This Row],[Valor FOB (Free On Board]]>=5000, "Mediano", "Pequeno")) -> Mediano | P39: =VLOOKUP(Tabla1[[#This Row],[País Destino]], '3. Mercados'!$C$4:$F$9, 4, FALSE) -> Estratégico | Q39: =IF(AND(Tabla1[[#This Row],[Tipo de Mercado]]="Estratégico", Tabla1[[#This Row],[Margen]]>=30%), "Alta", IF(AND(Tabla1[[#This Row],[Tipo de Mercado]]="Estratégico", Tabla1[[#This Row],[Margen]]<30%), "Media", IF(AND(Tabla1[[#This Row],[Tipo de Mercado]]="Potencial", Tabla1[[#This Row],[Margen]]>=30%), "Media", "Baja"))) -> Media
B40: EX037 | C40: 46333 | D40: Comercial Maya | E40: P001 | F40: Guatemala | G40: 1150 | H40: 6.5 | I40: 4.1 | J40: Entregado | K40: =+Tabla1[[#This Row],[Unidades]]*Tabla1[[#This Row],[Precio FOB]] -> 7475 | L40: =+Tabla1[[#This Row],[Unidades]]*Tabla1[[#This Row],[Costo Unitario]] -> 4715 | M40: =+Tabla1[[#This Row],[Valor FOB (Free On Board]]-Tabla1[[#This Row],[Costo total]] -> 2760 | N40: =+Tabla1[[#This Row],[Utilidad:]]/Tabla1[[#This Row],[Valor FOB (Free On Board]] -> 0.36923077 | O40: =+IF(Tabla1[[#This Row],[Valor FOB (Free On Board]]>=10000, "Grande", IF(Tabla1[[#This Row],[Valor FOB (Free On Board]]>=5000, "Mediano", "Pequeno")) -> Mediano | P40: =VLOOKUP(Tabla1[[#This Row],[País Destino]], '3. Mercados'!$C$4:$F$9, 4, FALSE) -> Estratégico | Q40: =IF(AND(Tabla1[[#This Row],[Tipo de Mercado]]="Estratégico", Tabla1[[#This Row],[Margen]]>=30%), "Alta", IF(AND(Tabla1[[#This Row],[Tipo de Mercado]]="Estratégico", Tabla1[[#This Row],[Margen]]<30%), "Media", IF(AND(Tabla1[[#This Row],[Tipo de Mercado]]="Potencial", Tabla1[[#This Row],[Margen]]>=30%), "Media", "Baja"))) -> Alta | R40: =VLOOKUP(Tabla1[[#This Row],[País Destino]], '3. Mercados'!$C$4:$F$9, 2, FALSE) -> Centroamérica
B41: EX038 | C41: 46341 | D41: Distribuidora Tica | E41: P005 | F41: Costa Rica | G41: 580 | H41: 12.5 | I41: 8.7 | J41: Embarcado | K41: =+Tabla1[[#This Row],[Unidades]]*Tabla1[[#This Row],[Precio FOB]] -> 7250 | L41: =+Tabla1[[#This Row],[Unidades]]*Tabla1[[#This Row],[Costo Unitario]] -> 5046 | M41: =+Tabla1[[#This Row],[Valor FOB (Free On Board]]-Tabla1[[#This Row],[Costo total]] -> 2204 | N41: =+Tabla1[[#This Row],[Utilidad:]]/Tabla1[[#This Row],[Valor FOB (Free On Board]] -> 0.304 | O41: =+IF(Tabla1[[#This Row],[Valor FOB (Free On Board]]>=10000, "Grande", IF(Tabla1[[#This Row],[Valor FOB (Free On Board]]>=5000, "Mediano", "Pequeno")) -> Mediano | P41: =VLOOKUP(Tabla1[[#This Row],[País Destino]], '3. Mercados'!$C$4:$F$9, 4, FALSE) -> Estratégico | Q41: =IF(AND(Tabla1[[#This Row],[Tipo de Mercado]]="Estratégico", Tabla1[[#This Row],[Margen]]>=30%), "Alta", IF(AND(Tabla1[[#This Row],[Tipo de Mercado]]="Estratégico", Tabla1[[#This Row],[Margen]]<30%), "Media", IF(AND(Tabla1[[#This Row],[Tipo de Mercado]]="Potencial", Tabla1[[#This Row],[Margen]]>=30%), "Media", "Baja"))) -> Alta
B42: EX039 | C42: 46349 | D42: Iberia Foods | E42: P003 | F42: España | G42: 1300 | H42: 4.8 | I42: 3.2 | J42: Pendiente | K42: =+Tabla1[[#This Row],[Unidades]]*Tabla1[[#This Row],[Precio FOB]] -> 6240 | L42: =+Tabla1[[#This Row],[Unidades]]*Tabla1[[#This Row],[Costo Unitario]] -> 4160 | M42: =+Tabla1[[#This Row],[Valor FOB (Free On Board]]-Tabla1[[#This Row],[Costo total]] -> 2080 | N42: =+Tabla1[[#This Row],[Utilidad:]]/Tabla1[[#This Row],[Valor FOB (Free On Board]] -> 0.33333333 | O42: =+IF(Tabla1[[#This Row],[Valor FOB (Free On Board]]>=10000, "Grande", IF(Tabla1[[#This Row],[Valor FOB (Free On Board]]>=5000, "Mediano", "Pequeno")) -> Mediano | P42: =VLOOKUP(Tabla1[[#This Row],[País Destino]], '3. Mercados'!$C$4:$F$9, 4, FALSE) -> Potencial | Q42: =IF(AND(Tabla1[[#This Row],[Tipo de Mercado]]="Estratégico", Tabla1[[#This Row],[Margen]]>=30%), "Alta", IF(AND(Tabla1[[#This Row],[Tipo de Mercado]]="Estratégico", Tabla1[[#This Row],[Margen]]<30%), "Media", IF(AND(Tabla1[[#This Row],[Tipo de Mercado]]="Potencial", Tabla1[[#This Row],[Margen]]>=30%), "Media", "Baja"))) -> Media
...

Sheet 2. Productos
C2: Catálogo de Productos
C3: Código | D3: Producto | E3: Categoría | F3: Unidad de Medida
C4: P001 | D4: Café especial | E4: Café | F4: Kg
C5: P002 | D5: Cacao en grano | E5: Cacao | F5: Kg
C6: P003 | D6: Miel natural | E6: Apícola | F6: Kg
C7: P004 | D7: Maní procesado | E7: Semillas | F7: Kg
C8: P005 | D8: Aceite de ajonjolí | E8: Aceites | F8: Litro

Sheet 3. Mercados
C2: Mercados
C3: País | D3: Región | E3: Arancel % | F3: Clasificación
C4: EE.UU. | D4: Norteamérica | E4: 0.05 | F4: Estratégico
C5: México | D5: Norteamérica | E5: 0.08 | F5: Potencial
C6: Guatemala | D6: Centroamérica | E6: 0.03 | F6: Estratégico
C7: Costa Rica | D7: Centroamérica | E7: 0.02 | F7: Estratégico
C8: El Salvador | D8: Centroamérica | E8: 0.02 | F8: Potencial
C9: España | D9: Europa | E9: 0.1 | F9: Potencial

Sheet Preguntas
B2: Nº | C2: Pregunta | D2: Respuesta
B3: 1 | C3: ¿Cuántas operaciones internacionales se realizaron? | D3: 24 operaciones
B4: 2 | C4: ¿Cuántas operaciones están pendientes? | D4: 4 operaciones
B5: 3 | C5: ¿Cuál es el país con mayor cantidad de operaciones? | D5: EE. UU. y México, con 6 operaciones cada uno
B6: 4 | C6: ¿Cuál es el país que genera mayor valor FOB? | D6: EE. UU., con $52,390
B7: 5 | C7: ¿Cuál es el producto más exportado por unidades? | D7: Café especial (P001), con 26,180 kg
B8: 6 | C8: ¿Cuál es el producto que genera mayor utilidad? | D8: Café especial (P001), con una utilidad total de $62,832
B9: 7 | C9: ¿Cuál es el mercado con mayor margen promedio? | D9: Todos presentan el mismo margen promedio: 36.92%
B10: 8 | C10: ¿Cuántas operaciones tienen rentabilidad alta? | D10: 15 operaciones tienen prioridad comercial Alta
B11: 9 | C11: ¿Cuánto se exportó hacia Centroamérica? | D11: $58,045 FOB
B12: 10 | C12: ¿Cuánto se exportó hacia Norteamérica? | D12: $88,985 FOB
B13: 11 | C13: ¿Cuánto se exportó hacia Europa? | D13: $23,140 FOB
B16: 12. ¿Qué operaciones tienen prioridad comercial alta?
B17: Las operaciones clasificadas con prioridad comercial Alta son:
B18: EX002, EX007, EX012, EX021, EX033, EX037, EX041, EX053, EX057, EX061, EX073, EX077, EX081, EX091 y EX097.
B19: En total: 15 operaciones.
C21: 13. ¿Qué clientes generan mayor valor de exportación?
B24: Cliente | C24: Operaciones | D24: Valor FOB
B25: Global Foods | C25: 6 | D25: $52,390
B26: Comercial Azteca | C26: 6 | D26: $36,595
B27: Comercial Maya | C27: 5 | D27: $33,085
B28: Distribuidora Tica | C28: 4 | D28: $24,960
B29: Iberia Foods | C29: 3 | D29: $23,140
B30: Por lo tanto, Global Foods es el cliente que genera mayor valor de exportación, con $52,390 FOB.
C32: 14. ¿Qué operaciones requieren atención por estar pendientes?
B33: Operación | C33: Cliente | D33: País destino | E33: Valor FOB
B34: EX012 | C34: Comercial Maya | D34: Guatemala | E34: $4,550
B35: EX025 | C35: Comercial Azteca | D35: México | E35: $6,175
B36: EX065 | C36: Comercial Azteca | D36: México | E36: $5,785
B37: EX085 | C37: Comercial Azteca | D37: México | E37: $6,435

Sheet  Gráficos y  Tablas dinámicas  
A1: Valor FOB por país
A3: Etiquetas de fila | B3: Suma de Valor FOB (Free On Board | I3: Este gráfico demuestra que EE.UU. se consolida como el principal mercado de exportación para NicaExport Trading, S.A. durante este período, liderando la generación de ingresos divisas. Costa Rica se registra con la menor participación económica.
A4: Costa Rica | B4: 113544
A5: EE.UU. | B5: 168745
A6: España | B6: 136328
A7: Guatemala | B7: 119335
A8: México | B8: 120313
A9: Total general | B9: 658265
A18: Utilidad por producto
I22: Al evaluar la relación de Utilidad Neta por cartera de productos, se observa que el Café especial es el portafolio más rentable para la organización, aportando el mayor volumen de ganancias líquidas absolutas, Por otra parte, el producto mani procesado, a pesar de sus volúmenes transaccionados, genera el menor retorno financiero
A24: Etiquetas de fila | B24: Suma de Utilidad:
A25: P001 | B25: 62832
A26: P002 | B26: 36800
A27: P003 | B27: 38688
A28: P004 | B28: 33534
A29: P005 | B29: 42218
A30: Total general | B30: 214072
A36: Ventas por región
I38: El gráfico de distribución circular evidencia la composición del Valor FOB por bloques regionales, donde Norteamérica abarca la mayor cuota de mercado con un 52.29% del total de las exportaciones. Las regiones de Centroamérica y Europa actúan como mercados de acompañamiento con el 34.11% y 13.60% respectivamente.
A39: Etiquetas de fila | B39: Suma de Valor FOB (Free On Board
A40: Centroamérica | B40: 58045
A41: Europa | B41: 23140
A42: Norteamérica | B42: 88985
A43: Total general | B43: 170170
A55: Operaciones por clasificación de prioridad
A57: Etiquetas de fila | B57: Cuenta de ID_Operación
A58: Alta | B58: 48
A59: Baja | B59: 6
A60: Media | B60: 46
A61: Total general | B61: 100
